Workbook

Sheet harsh desai
A1: Transactions Type | B1: date of investment | C1: agreement name | D1: amount of investment | E1: repayment dates | F1: repayment amount | H1: RoI | K1: Repayment as per 21% | L1: Repayment as per 30 | P1: Extra returns earning due to upgrated in roi on Investment
A2: investment | B2: 1st oct 23 | C2: Punita desai | D2: 200000 | H2: 21 | K2: =D2*H2/100 -> 42000 | L2: =D2*H23 -> 60000 | P2: =L2-K2 -> 18000
A3: investment | B3: 5th oct 23 | C3: Punita desai | D3: 200000 | H3: 21 | K3: =D3*H3/100 -> 42000 | L3: =D3*H24 -> 60000 | P3: =L3-K3 -> 18000
A4: investment | B4: 5th oct 23 | C4: Punita desai | D4: 100000 | H4: 21 | K4: =D4*H4/100 -> 21000 | L4: =D4*H25 -> 30000 | P4: =L4-K4 -> 9000
A5: repayment | E5: 31st oct 23 | F5: 105000 | G5: punita desai
A6: investment | B6: 4th nov | C6: Harsh Desai | D6: 200000 | H6: 21 | K6: =D6*H6/100 -> 42000 | L6: =D6*H$27 -> 60000 | P6: =L6-K6 -> 18000
A7: investment | B7: 4th nov | C7: Harsh Desai | D7: 200000 | H7: 21 | K7: =D7*H7/100 -> 42000 | L7: =D7*H$27 -> 60000 | P7: =L7-K7 -> 18000
A8: investment | B8: 4th nov | C8: Harsh Desai | D8: 99000 | H8: 21 | K8: =D8*H8/100 -> 20790 | L8: =D8*H$27 -> 29700 | P8: =L8-K8 -> 8910
A9: investment | B9: 4th nov | C9: Janvhi Soni | D9: 25000 | H9: 21 | K9: =D9*H9/100 -> 5250 | L9: =D9*H$27 -> 7500 | P9: =L9-K9 -> 2250
A10: investment | B10: 5th nov | C10: Janvhi Soni | D10: 375000 | H10: 21 | K10: =D10*H10/100 -> 78750 | L10: =D10*H$27 -> 112500 | P10: =L10-K10 -> 33750
A11: investment | B11: 5th nov | C11: Janvhi Soni | D11: 100000 | H11: 21 | K11: =D11*H11/100 -> 21000 | L11: =D11*H$27 -> 30000 | P11: =L11-K11 -> 9000
A12: repayment | E12: 30th nov 23 | F12: 105000 | G12: punita desai
A13: repayment | E13: 30th nov 23 | F13: 105000 | G13: harsh desai
A14: repayment | E14: 3rd dec | F14: 105000 | G14: janvhi Soni
A15: investment | B15: 3rd dec 23 | C15: punita desai | D15: 100000 | H15: 28 | K15: =D15*H15/100 -> 28000 | L15: =D15*H$23 -> 30000 | P15: =L15-K15 -> 2000
A16: investment | B16: 4th dec 23 | C16: punita desai | D16: 200000 | H16: 28 | K16: =D16*H16/100 -> 56000 | L16: =D16*H$23 -> 60000 | P16: =L16-K16 -> 4000
A17: investment | B17: 4th dec 23 | C17: punita desai | D17: 200000 | H17: 28 | K17: =D17*H17/100 -> 56000 | L17: =D17*H$23 -> 60000 | P17: =L17-K17 -> 4000
A18: investment | B18: 4th dec 23 | C18: Punita desai | D18: 200000 | H18: 28 | K18: =D18*H18/100 -> 56000 | L18: =D18*H$23 -> 60000 | P18: =L18-K18 -> 4000
A19: investment | B19: 6th dec 23 | C19: Punita desai | D19: 200000 | H19: 28 | K19: =D19*H19/100 -> 56000 | L19: =D19*H$23 -> 60000 | P19: =L19-K19 -> 4000
A20: investment | B20: 6th dec 23 | C20: Punita desai | D20: 100000 | H20: 28 | K20: =D20*H20/100 -> 28000 | L20: =D20*H$23 -> 30000 | P20: =L20-K20 -> 2000
A21: investment | B21: 11th dec 23 | C21: Punita desai | D21: 100000 | H21: 28 | K21: =D21*H21/100 -> 28000 | L21: =D21*H$23 -> 30000 | P21: =L21-K21 -> 2000
A22: repayment | E22: 3rd jan 23 | F22: 588000 | G22: repayment for harsh and punita desai | H22: adjusted in new investment
A23: investment | B23: 03rd Jan 24 | C23: harsh desai | D23: 200000 | H23: 0.3
A24: investment | B24: 03rd Jan 24 | C24: harsh desai | D24: 200000 | H24: 0.3
A25: investment | B25: 04th Jan 24 | C25: harsh desai | D25: 200000 | H25: 0.3
A26: repayment | E26: 4th jan | F26: 105000 | G26: Janvhi mam | H26: paid from harsh desai
A27: investment | B27: 05th Jan 24 | C27: Harsh desai | D27: 200000 | H27: 0.3
A28: investment | B28: 8th jan 24 | C28: Harsh desai | D28: 200000 | H28: 0.3
A29: investment | B29: 8th jan 24 | C29: Harsh desai | D29: 200000 | H29: 0.3
A30: investment | B30: 8th jan 24 | C30: Harsh desai | D30: 7000 | H30: 0.3
A31: repayment | E31: 8th feb 24 | F31: 105000 | G31: Janvhi soni
A32: investment | B32: 8th feb 24 | C32: janvhi soni | D32: 100000 | E32: adjusted | H32: 0.3
A33: repayment | E33: 8th feb 24 | F33: 588000 | G33: punita desai
A34: investment | B34: 8th feb 24 | C34: punita desai | D34: 500000 | E34: adjusted | H34: 0.3
A35: repayment | E35: 12th feb 24 | F35: 630000
A36: investment | B36: 12th feb 24 | C36: harsh desai | D36: 500000 | E36: adjusted | H36: 0.3
A37: repayment | E37: 12th Feb 24 | F37: 90000 | G37: harsh desai
A38: repayment | E38: 28th march 24 | F38: 150000 | G38: janvhi soni | P38: =SUM(P2:P21) -> 156910
A39: repayment | E39: 31st march 24 | F39: 500000 | G39: punita desai
E40: 31st march 24 | F40: 332000 | G40: punita desai
...

Sheet Harsh prajapati
A1: Transaction types | B1: date of investment | C1: agreement name | D1: amount of investment | E1: repayment dates | F1: repayment amount | H1: RoI
A2: Investment | B2: 15th Feb 24 | C2: Harsh prajapati | D2: 50000 | H2: 15
A3: Repayment | E3: 16th May 24 | F3: 3750
E4: 08th May 24 | F4: 3750
E5: 09th Mar 24 | F5: 3750
H6: capital returned
D10: =SUM(D2) -> 50000 | F10: =SUM(F3:F8) -> 11250 | H10: =F10/D10 -> 0.225 | J10: =D10-F10 -> 38750
B13: IN CASE OF DISCONTINUE FROM INVESTMENT CAPITAL WILL START REPAYMENT FROM END OF SEPTEMBER 24
C15: INVESTMENT OF | D15: MIN RETURNS | E15: USED MONTHS | G15: PER MONTH INTREST | H15: TOTAL INTREST TILL DATE ON INVESTMENT | I15: TOTAL AMOUNT TO REPAY
A16: oct | B16: 1st investment | C16: =SUM(D2) -> 50000 | D16: 0 | E16: 5.5 | G16: =C16*D16/100 -> 0 | H16: =G16*E16 -> 0 | I16: =C16+H16 -> 50000
I19: =SUM(I16:I17) -> 50000
G21: REPAYMENT TILL NOW WE MADE | I21: =F10 -> 11250
G24: YOU WILL NEED TO REPAY US BACK TO DISCONTINUE WITH PLANS | I24: =I19-I21 -> 38750 | K24: Repayment will start from September 24 end | M24: will be paid on
K25: =I24/3 -> 12916.667 | L25: Sep end | M25: ie. Oct 5th
K26: =K25 -> 12916.667 | L26: Oct end | M26: ie Nov 5th
K27: =K26 -> 12916.667 | L27: Nov end | M27: ie. Dec 5th

Sheet smit amin
A1: Transaction types | B1: date of investment | C1: agreement name | D1: amount of investment | E1: repayment dates | F1: repayment amount | J1: Roi
A2: investment | B2: 20th Dec 23 | C2: Smit Amin | D2: 200000 | J2: 0.12
A3: repayment | E3: 31st Dec 23 | F3: 8000
A4: repayment | E4: 31st dec 23
A5: repayment | E5: 5th Feb 24 | F5: 24000
A6: Repayment | E6: 08th Mar 24 | F6: 24000
A7: Repayment | E7: 30th April 24 | F7: 24000
E8: 7th June 24 | F8: 24000
H12: capital returned | K12: 3% returns for 5th Sep, 5th Oct, 5th Nov respectively
D13: =SUM(D2) -> 200000 | F13: =SUM(F3:F11) -> 104000 | H13: =F13/D13 -> 0.52 | K13: =(D13-F13)*3/100 -> 2880
K14: =K13 -> 2880
K15: =K14 -> 2880
D16: IN CASE OF DISCONTINUE FROM INVESTMENT CAPITAL WILL START REPAYMENT FROM END OF Nov 24
D20: capital | E20: % of returns capital | F20: month of used of capital | H20: per month min intrest | I20: total intrest for the month your funds is being used by us
D21: =D2 -> 200000 | E21: 3 | F21: 8 | H21: =D21*E21/100 -> 6000 | I21: =H21*F21+D21 -> 248000
H26: REPAYMENT TILL NOW WE MADE | I26: =F13 -> 104000 | J26: =F8 -> 24000
H28: NEED TO REPAY as on DISCONTINUE WITH PLANS | I28: =I21-I26 -> 144000 | L28: Repayment will start from September 24 end
L29: =I28/3 -> 48000 | M29: Sep to i.e till Dec 5th
L30: =L29 -> 48000 | M30: Oct end i.e till Jan 5th
L31: =L30 -> 48000 | M31: Nov end i.e Feb 5th

Sheet dineshbhai paperiya
A1: Transaction types | B1: date of investment | C1: agreement name | D1: amount of investment | E1: repayment dates | F1: repayment amount | J1: Roi
A2: investment | B2: 30th March 24 | C2: Dineshbhai paperiya | D2: 350000 | J2: 0.15
A3: repayment | E3: 8th May 24 | F3: 59500
A4: repayment | E4: june | F4: 0
A5: repayment | E5: july | F5: 0
H9: capital returned | K9: 5% returns for 5th August, sept, oct respectively
D10: =SUM(D2) -> 350000 | F10: =SUM(F3:F8) -> 59500 | H10: =F10/D10 -> 0.17 | K10: =(D10-F10)*3/100 -> 8715
K11: =K10 -> 8715
K12: =K11 -> 8715
D13: IN CASE OF DISCONTINUE FROM INVESTMENT CAPITAL WILL START REPAYMENT FROM END OF SEPTEMBER 24
D17: capital | E17: % of returns capital | F17: month of used of capital | H17: per month min intrest | I17: total intrest for the month your funds is being used by us
D18: =D2 -> 350000 | E18: 3 | F18: 4 | H18: =D18*E18/100 -> 10500 | I18: =H18*F18+D18 -> 392000
H23: REPAYMENT TILL NOW WE MADE | I23: =F10 -> 59500 | J23: =F7
H25: NEED TO REPAY as on DISCONTINUE WITH PLANS | I25: =I18-I23 -> 332500 | L25: Repayment will start from September 24 end
L26: =I25/3 -> 110833.33 | M26: Sep to i.e till oct 5th
L27: =L26 -> 110833.33 | M27: Oct end i.e till nov 5th
L28: =L27 -> 110833.33 | M28: Nov end i.e dec 5th

Sheet Sunil malvia
A1: Transaction types | B1: date of investment | C1: Agreement name | D1: amount of investment | E1: repayment dates | F1: repayment amount
A2: Investment | B2: 25th sep 23 | C2: Sunil malvia | D2: 100
B3: 26th sep 23 | D3: 90000
B4: 26th sep 23 | D4: 50000
B5: 27th sep 23 | D5: 90000
B6: 27th sep 23 | D6: 50000
B7: 28th sep 23 | D7: 90000
B8: 29th sep 23 | D8: 50000
B9: 30th sep 23 | D9: 80000
A10: repayment | E10: 31st oct 23 | F10: 140000
E11: 30th nov 23 | F11: 140000 | H11: 500100 | J11: investment till date
E12: 3rd jan 24 | F12: 140000 | H12: 420100 | I12: =H11-H12 -> 80000 | J12: paid till date | K12: balance capital with me
E13: 28th Jan 24 | F13: 100
B14: 28th jan 24 | D14: 90000
B15: 28th jan 24 | D15: 90000
B16: 29th jan 24 | D16: 9000
B17: 29th jan 24 | D17: 25000
B18: 29th jan 24 | D18: 20000
B19: 30th jan 24 | D19: 91000
B20: 30th jan 24 | D20: 25000
B21: 30th jan 24 | D21: 10000 | H21: repayment | I21: total capital out of this investment | J21: total balance capital with me
A22: repayment | E22: 30th jan 24 | F22: 140000 | H22: 140000 | I22: 360000 | J22: =SUM(I22:I23)-SUM(H22:H30) -> 1090000 | K22: balance capital with me
B23: 7th feb 24 | D23: 1000000 | I23: 1000000
E24: 18th mar 24 | F24: 25000 | H24: 25000
E25: 20th mar 24 | F25: 20000 | H25: 20000
E26: 28th mar 24 | F26: 10000 | H26: 10000
E27: 11th april 24 | F27: 20000 | H27: 20000
E28: 5th may 24 | F28: 20000 | H28: 20000
E29: 11th may 24 | F29: 30000 | H29: 30000
E30: 16th june 24 | F30: 5000 | H30: 5000
H35: capital returned | J35: Min Returns
D36: =SUM(D2:D34) -> 1860100 | F36: =SUM(F2:F34) -> 690100 | H36: =F36/D36 -> 0.37100156
C42: IN CASE OF DISCONTINUE FROM INVESTMENT CAPITAL WILL START REPAYMENT FROM END OF SEPTEMBER 24
D44: INVESTMENT OF | E44: MIN RETURNS | F44: USED MONTHS | H44: PER MONTH INTREST | I44: TOTAL INTREST TILL DATE ON INVESTMENT | J44: TOTAL AMOUNT TO REPAY
C45: 1st investment | D45: =D2 -> 100 | E45: 3 | F45: 6 | H45: =D45*E45/100 -> 3 | I45: =H45*F45 -> 18 | J45: =D45+I45 -> 118
J49: =SUM(J45:J47) -> 118
H52: REPAYMENT TILL NOW WE MADE | J52: =F36 -> 690100
H54: YOU WILL NEED TO REPAY US BACK TO DISCONTINUE WITH PLANS | J54: =J49-J52 -> -689982 | L54: Repayment will start from September 24 end
L55: =J54/3 -> -229994 | M55: Sep end
L56: =L55 -> -229994 | M56: Oct end
...

Sheet Ajay sing
A1: Transaction types | B1: date of investment | C1: Agreement name | D1: amount of investment | E1: repayment dates | F1: repayment amount | J1: % of returns
A2: Investment | B2: 3rd Nov 23 | C2: Ajay Somata | D2: 500000 | H2: 500000 | J2: 21 | L2: =500000*21/100 -> 105000
A3: Repayment | E3: 30th nov 23 | F3: 105000 | G3: 5000 paid and 1 lakhs settle in 5 lakhs | I3: 5000
A4: Investment | B4: 30th Nov 23 | D4: =100000+400000 -> 500000 | H4: 400000 | J4: 21 | L4: =500000*21/100 -> 105000
A5: repayment | E5: 03rd jan 24 | F5: 105000 | I5: 105000
A6: repayment | E6: 05th jan 24 | F6: 105000 | I6: 105000
A7: Investment | B7: 31st Jan 24 | D7: 200000 | J7: 25 | L7: =500000*J7/100 -> 125000
A8: Investment | B8: 31st Jan 24 | D8: 100000 | J8: 21
A9: repayment | F9: 210000 | G9: Paid 10k and below 2 laks was settle as investment | H9: 300000 | I9: 10000
A10: Investment | B10: 16th feb 24 | D10: 200000 | J10: 0.21 | L10: 335000
A11: repayment | E11: 4th March 24 | F11: 335000 | H11: 165000 | L11: 60000
A12: Investment | B12: 4th Mar 24 | D12: 90000 | L12: 15000
B13: 5th mar 24 | D13: 60000
B14: 5th mar 24 | D14: 15000 | H14: =SUM(H1:H13) -> 1365000
B15: 5th Mar 24 | D15: =F11 -> 335000 | J15: 0.05
A16: Repayment | B16: 31st May 24 | E16: 31st May 24 | F16: 300000 | I16: 300000
H20: capital returned | J20: Min Returns
D21: =SUM(D2:D19) -> 2000000 | F21: =SUM(F2:F20) -> 1160000 | H21: =F21/D21 -> 0.58 | I21: =Sum(I1:I19) -> 525000
J24: =H14-I21 -> 840000
C27: IN CASE OF DISCONTINUE FROM INVESTMENT CAPITAL WILL START REPAYMENT FROM END OF SEPTEMBER 24
D29: INVESTMENT OF | E29: MIN RETURNS | F29: USED MONTHS | H29: PER MONTH INTREST | I29: TOTAL INTREST TILL DATE ON INVESTMENT | J29: TOTAL AMOUNT TO REPAY
C30: 1st investment | D30: =D2 -> 500000 | F30: 9 | H30: =D30*E30/100 -> 0 | I30: =H30*F30 -> 0 | J30: =D30+I30 -> 500000
C31: 2nd investment | D31: 500000 | F31: 7 | H31: =D31*E31/100 -> 0 | I31: =H31*F31 -> 0 | J31: =D31+I31 -> 500000
C32: 3rd Investment | D32: 500000 | F32: 6 | H32: =D32*E32/100 -> 0 | I32: =H32*F32 -> 0 | J32: =D32+I32 -> 500000
C33: 4th investment | D33: 500000 | F33: 5 | H33: =D33*E33/100 -> 0 | I33: =H33*F33 -> 0 | J33: =D33+I33 -> 500000
J35: =SUM(J30:J33) -> 2000000
H38: REPAYMENT TILL NOW WE MADE | J38: =F21 -> 1160000
H40: YOU WILL NEED TO REPAY US BACK TO DISCONTINUE WITH PLANS | J40: =J35-J38 -> 840000 | L40: Repayment will start from September 24 end
L41: =J40/3 -> 280000 | M41: 5th Oct 24
L42: =L41 -> 280000 | M42: 5th Nov 24
L43: =L42 -> 280000 | M43: 5th Dec 24

Sheet vikas zhakar
A1: Transaction types | B1: date of investment | C1: Agreement name | D1: amount of investment | E1: repayment dates | F1: repayment amount
A2: Investment | B2: 3rd Jan 24 | C2: Shubham Dhariwal | D2: 600000
E3: 45360 | F3: 25000
E4: 45371 | F4: 20000
E5: 45379 | F5: 120000
E6: 45383 | F6: 162000
J9: 0.05
H10: capital returned | J10: Min Returns
D11: =SUM(D2:D8) -> 600000 | F11: =SUM(F2:F8) -> 327000 | H11: =F11/D11 -> 0.545 | J11: =(D11)*5/100 -> 30000 | K11: 5th July
J12: =J11 -> 30000 | K12: 5th Aug
J13: =J12 -> 30000 | K13: 5th sep
C17: IN CASE OF DISCONTINUE FROM INVESTMENT CAPITAL WILL START REPAYMENT FROM END OF SEPTEMBER 24
D19: INVESTMENT OF | E19: MIN RETURNS | F19: USED MONTHS | H19: PER MONTH INTREST | I19: TOTAL INTREST TILL DATE ON INVESTMENT | J19: TOTAL AMOUNT TO REPAY
C20: 1st investment | D20: =D2 -> 600000 | E20: 3 | F20: 6 | H20: =D20*E20/100 -> 18000 | I20: =H20*F20 -> 108000 | J20: =D20+I20 -> 708000
J24: =SUM(J20:J22) -> 708000
H27: REPAYMENT TILL NOW WE MADE | J27: =F11 -> 327000
H29: YOU WILL NEED TO REPAY US BACK TO DISCONTINUE WITH PLANS | J29: =J24-J27 -> 381000 | L29: Repayment will start from September 24 end
L30: =J29/3 -> 127000 | M30: Sep end
L31: =L30 -> 127000 | M31: Oct end
L32: =L31 -> 127000 | M32: Nov end

Sheet amar singh
A1: Transaction types | B1: date of investment | C1: Agreement name | D1: amount of investment | E1: repayment dates | F1: repayment amount
A2: Investment | B2: 3rd Jan 24 | C2: Shubham Dhariwal | D2: 600000
E3: 45360 | F3: 25000
E4: 45371 | F4: 20000
E5: 45379 | F5: 120000
E6: 45383 | F6: 162000
J9: 0.05
H10: capital returned | J10: Min Returns
D11: =SUM(D2:D8) -> 600000 | F11: =SUM(F2:F8) -> 327000 | H11: =F11/D11 -> 0.545 | J11: =(D11)*5/100 -> 30000 | K11: 5th July
J12: =J11 -> 30000 | K12: 5th Aug
J13: =J12 -> 30000 | K13: 5th sep
C17: IN CASE OF DISCONTINUE FROM INVESTMENT CAPITAL WILL START REPAYMENT FROM END OF SEPTEMBER 24
D19: INVESTMENT OF | E19: MIN RETURNS | F19: USED MONTHS | H19: PER MONTH INTREST | I19: TOTAL INTREST TILL DATE ON INVESTMENT | J19: TOTAL AMOUNT TO REPAY
C20: 1st investment | D20: =D2 -> 600000 | E20: 3 | F20: 6 | H20: =D20*E20/100 -> 18000 | I20: =H20*F20 -> 108000 | J20: =D20+I20 -> 708000
J24: =SUM(J20:J22) -> 708000
H27: REPAYMENT TILL NOW WE MADE | J27: =F11 -> 327000
H29: YOU WILL NEED TO REPAY US BACK TO DISCONTINUE WITH PLANS | J29: =J24-J27 -> 381000 | L29: Repayment will start from September 24 end
L30: =J29/3 -> 127000 | M30: Sep end
L31: =L30 -> 127000 | M31: Oct end
L32: =L31 -> 127000 | M32: Nov end

Sheet Shubham Dhariwal
A1: Transaction types | B1: date of investment | C1: Agreement name | D1: amount of investment | E1: repayment dates | F1: repayment amount
A2: Investment | B2: 3rd Jan 24 | C2: Shubham Dhariwal | D2: 600000
E3: 45360 | F3: 25000
E4: 45371 | F4: 20000
E5: 45379 | F5: 120000
E6: 45383 | F6: 162000
J9: 0.05
H10: capital returned | J10: Min Returns
D11: =SUM(D2:D8) -> 600000 | F11: =SUM(F2:F8) -> 327000 | H11: =F11/D11 -> 0.545 | J11: =(D11)*5/100 -> 30000 | K11: 5th July
J12: =J11 -> 30000 | K12: 5th Aug
J13: =J12 -> 30000 | K13: 5th sep
C17: IN CASE OF DISCONTINUE FROM INVESTMENT CAPITAL WILL START REPAYMENT FROM END OF SEPTEMBER 24
D19: INVESTMENT OF | E19: MIN RETURNS | F19: USED MONTHS | H19: PER MONTH INTREST | I19: TOTAL INTREST TILL DATE ON INVESTMENT | J19: TOTAL AMOUNT TO REPAY
C20: 1st investment | D20: =D2 -> 600000 | E20: 3 | F20: 6 | H20: =D20*E20/100 -> 18000 | I20: =H20*F20 -> 108000 | J20: =D20+I20 -> 708000
J24: =SUM(J20:J22) -> 708000
H27: REPAYMENT TILL NOW WE MADE | J27: =F11 -> 327000
H29: YOU WILL NEED TO REPAY US BACK TO DISCONTINUE WITH PLANS | J29: =J24-J27 -> 381000 | L29: Repayment will start from September 24 end
L30: =J29/3 -> 127000 | M30: Sep end
L31: =L30 -> 127000 | M31: Oct end
L32: =L31 -> 127000 | M32: Nov end

Sheet sachin singh
A1: Transaction types | B1: date of investment | C1: agreement name | D1: amount of investment | E1: repayment dates | F1: repayment amount
A2: investment | B2: 21st July 24 | C2: Sachin Singh | D2: 25000 | J2: 0.1 | M2: =D2*J2 -> 2500
E3: 31st Aug 23 | F3: 2500
E4: 30th sep 23 | F4: 2500
E5: 31st oct 23 | F5: 2500
E6: 4th dec 23 | F6: 2500
E7: 3rd jan 23 | F7: 2500
E8: 8th feb 23 | F8: 2500
E9: 7th mar 23 | F9: 2500
E10: 7th apr 23 | F10: 2500
E11: 4th may 23 | F11: 2500
H16: capital returned
D17: =SUM(D2:D15) -> 25000 | F17: =SUM(F2:F15) -> 22500 | H17: =F17/D17 -> 0.9 | J17: 3% intrest to be
J18: =D17*3/100 -> 750 | K18: 5th july
J19: =J18 -> 750 | K19: 5th Aug
J20: =J19 -> 750 | K20: 5th Sep
D23: IN CASE OF DISCONTINUE FROM INVESTMENT CAPITAL WILL START REPAYMENT FROM END OF SEPTEMBER 24
D26: Capital Invested | E26: % of returns capital | F26: month of used of capital | H26: per month min intrest | I26: total intrest for the month your funds is being used by us
D27: =D17 -> 25000 | E27: 3 | F27: 9 | H27: =D27*E27/100 -> 750 | I27: =H27*F27 -> 6750
I32: =D27+I27 -> 31750
H34: REPAYMENT TILL NOW WE MADE | I34: =F17 -> 22500
H36: YOU WILL NEED TO REPAY US BACK TO DISCONTINUE WITH PLANS | I36: =I32-I34 -> 9250 | K36: Repayment will start from September 24 end
K37: =I36/3 -> 3083.3333 | L37: Sep end
K38: =K37 -> 3083.3333 | L38: Oct end
K39: =K38 -> 3083.3333 | L39: Nov end

Sheet nishant panchal
A1: Transaction types | B1: date of investment | C1: agreement name | D1: amount of investment | E1: repayment dates | F1: repayment amount
A2: Investment | B2: 7th oct 23 | C2: nishant Panchal | D2: 50000 | J2: 0.15 | M2: =D2*J2 -> 7500
A3: Repayment | E3: 30th nov 23 | F3: 3750
A4: Repayment | E4: 6th feb 23 | F4: 7500
A5: Repayment | E5: 9th mar 23 | F5: 7500
A6: Repayment | E6: 7th May 23 | F6: 3750
A7: Repayment | E7: 8th May 23 | F7: 3750
D11: =SUM(D2:D9) -> 50000 | F11: =SUM(F2:F9) -> 26250
D17: IN CASE OF DISCONTINUE FROM INVESTMENT CAPITAL WILL START REPAYMENT FROM END OF SEPTEMBER 24
D20: Capital | E20: % of returns capital | F20: month of used of capital | H20: per month min intrest | I20: total intrest for the month your funds is being used by us
D21: =D2 -> 50000 | E21: 3 | F21: 0 | H21: =D21*E21/100 -> 1500 | I21: =H21*F21 -> 0
H22: total amount to be paid | I22: =I21+D21 -> 50000
H23: payment we have done | I23: =SUM(F3:F7) -> 26250
H25: Balance to be paid | I25: =I22-I23 -> 23750

Sheet Laxmikant Mohanty
A1: Transaction types | B1: date of investment | C1: agreement name | D1: amount of investment | E1: repayment dates | F1: repayment amount | I1: 15% on 1.5 lakhs | J1: 20% on 2 lakhs
A2: investment | B2: 7th oct 23 | C2: Laxmikant Mohanty | D2: 150000 | H2: 15 | I2: =D2*15/100 -> 22500 | J2: =D8*20/100 -> 40000
A3: repayments | E3: 31st oct 23 | F3: 22500
A4: repayments | E4: 15th dec 23 | F4: 22500
E5: 17th Feb, 23 | F5: 22500
A6: repayments | E6: 04th marc 23 | F6: 22000
A7: repayments | E7: 04th marc 23 | F7: 500
A8: investment | C8: Laxmikant Mohanty | D8: 200000 | H8: 20
A9: repayments | E9: 06th apr | F9: 8000
A10: repayments | E10: 06th apr | F10: 22500
A11: repayments | E11: 2nd May | F11: 22500
A12: repayments | E12: 08th may | F12: 47500
E13: june
E14: july
E15: augus
H16: capital returned
D17: =SUM(D2:D8) -> 350000 | F17: =SUM(F2:F16) -> 190500 | H17: =F17/D17 -> 0.54428571 | J17: =D17*5/100 -> 17500
C19: balance capital | D19: =D17-F17 -> 159500
C20: one month intrest | D20: =D19*2/100 -> 3190 | H20: =D17-F17 -> 159500
C21: total months of intrest @2% min roi april-dec 24, jan25-Dec 25+jan 26 till july 26 calcualted | D21: =D20*27 -> 86130
D24: IN CASE OF DISCONTINUE FROM INVESTMENT CAPITAL WILL START REPAYMENT FROM END OF SEPTEMBER 24
D27: Capital | E27: % of returns capital | F27: month of used of capital | H27: per month min intrest | I27: total intrest for the month your funds is being used by us
D28: =D2 -> 150000 | E28: 0.75 | F28: 22 | H28: =D28*E28/100 -> 1125 | I28: =H28*F28 -> 24750
D29: =D8 -> 200000 | E29: 0.75 | F29: 19 | H29: =D29*E29/100 -> 1500 | I29: =H29*F29 -> 28500
H33: total amount to be paid | I33: =SUM(I28:I29)+D28+D29 -> 403250
H34: payment we have done | I34: =SUM(F14:F18) -> 190500
H36: Balance to be paid | I36: =I33-I34 -> 212750
H38: new balance to repay with intrest of 2% min intrest 3x of banks rate of intrest | I38: =D19+D21 -> 245630

Sheet dharmesh bhai
A1: Transaction types | B1: date of investment | C1: agreement name | D1: amount of investment | E1: repayment dates | F1: repayment amount | J1: ROI
A2: investment | B2: 15th sep 23 | C2: Dharmesh bhai | D2: 50000 | J2: 0.15
A3: repayments | E3: 01st Oct 23 | F3: 3750
A4: repayments | E4: 31st oct 23 | F4: 7500
A5: repayments | E5: 1st dec 23 | F5: 7500
A6: repayments | E6: 2nd jan 23 | F6: 7500
A7: repayments | E7: 05th feb 23 | F7: 7500
A8: repayments | E8: 05th Mar 23 | F8: 7500
A9: repayments | E9: 07th Apr 23 | F9: 7500
A10: repayments | E10: 07th May 23 | F10: 7500
H18: capital returned
D19: =SUM(D2:D16) -> 50000 | F19: =SUM(F2:F16) -> 56250 | H19: =F19/D19 -> 1.125

Sheet mohit vaghela
A1: Transaction types | B1: date of investment | C1: agreement name | D1: amount of investment | E1: repayment dates | F1: repayment amount | J1: Roi
A2: investment | B2: 30th Sep 23 | C2: Mohit vaghela | D2: 50000 | J2: 0.15
A3: repayment | E3: 01st nov 23 | F3: 7500
A4: repayment | E4: 1st Dec 23 | F4: 7500
A5: repayment | E5: 2nd Jan 24 | F5: 7500
A6: repayment | E6: 5th Feb 24 | F6: 7500
A7: repayment | E7: 05th Mar 24 | F7: 7500
A8: repayment | E8: 5th april 24 | F8: 7500
A9: repayment | E9: 7th May 24 | F9: 7500
H16: capital returned | K16: 5% returns for june july and aug
D17: =SUM(D2) -> 50000 | F17: =SUM(F3:F15) -> 52500 | H17: =F17/D17 -> 1.05 | K17: =(D17-F17)*3/100 -> -75
K18: =K17 -> -75
K19: =K18 -> -75
D20: IN CASE OF DISCONTINUE FROM INVESTMENT CAPITAL WILL START REPAYMENT FROM END OF SEPTEMBER 24
D24: capital | E24: % of returns capital | F24: month of used of capital | H24: per month min intrest | I24: total intrest for the month your funds is being used by us
D25: 50000 | E25: 3 | F25: =SUBTOTAL(2,F3:F10) -> 7 | H25: =D25*E25/100 -> 1500 | I25: =H25*F25 -> 10500
H26: total amount to be paid | I26: =I25+D25 -> 60500
H27: payment we have done | I27: =F17 -> 52500
H29: Balance to be paid | I29: =I26-I27 -> 8000 | K29: which will be paid in sep end

Sheet Dhiren bhai
A1: Transaction types | B1: date of investment | C1: agreement name | D1: amount of investment | E1: repayment dates | F1: repayment amount | J1: Roi
A2: investment | B2: 15th Septemeber 23 | C2: Dhiren Acharya | D2: 50000 | J2: 0.15
A3: repayment | E3: 1st oct 23 | F3: 3750
A4: repayment | E4: 31st Oct 23 | F4: 7500
A5: repayment | E5: 1st dec 23 | F5: 7500
A6: repayment | E6: 2nd jan 23 | F6: 7500
A7: repayment | E7: 05th feb 23 | F7: 7500
A8: repayment | E8: 05th Mar 23 | F8: 7500
A9: repayment | E9: 07th Apr 23 | F9: 7500
E10: 07th May 23 | F10: 7500
E11: june
E12: july
E13: aug
E14: sep
H16: capital returned | K16: 5% returns for june july and aug
D17: =SUM(D2) -> 50000 | F17: =SUM(F3:F15) -> 56250 | H17: =F17/D17 -> 1.125 | K17: =(D17-F17)*3/100 -> -187.5
K18: =K17 -> -187.5
K19: =K18 -> -187.5
D20: IN CASE OF DISCONTINUE FROM INVESTMENT CAPITAL WILL START REPAYMENT FROM END OF SEPTEMBER 24
D24: capital | E24: % of returns capital | F24: month of used of capital | H24: per month min intrest | I24: total intrest for the month your funds is being used by us
D25: 50000 | E25: 3 | F25: =SUBTOTAL(2,F3:F10) -> 8 | H25: =D25*E25/100 -> 1500 | I25: =H25*F25 -> 12000
H26: total amount to be paid | I26: =I25+D25 -> 62000
H27: payment we have done | I27: =F17 -> 56250
H29: Balance to be paid | I29: =I26-I27 -> 5750 | K29: which will be paid in September end

Sheet pravin bhai pambar
A1: Transaction types | B1: date of investment | C1: agreement name | D1: amount of investment | E1: repayment dates | F1: repayment amount | J1: Roi
A2: investment | B2: 30th dec 23 | C2: Pravin bhai Pambar | D2: 100000 | J2: 0.25
A3: investment | B3: 1st jan 24 | C3: Pravin bhai Pambar | D3: 300000 | J3: 0.25
A4: repayment | B4: 1st jan 24 | C4: Pravin bhai Pambar | D4: 100000 | J4: 0.25
A5: repayment | E5: 7th Feb 24 | F5: 99000
A6: repayment | E6: 9th feb 24 | F6: 26000
A7: repayment | E7: 12th Mar 24 | F7: 25000
A8: repayment | E8: 16th Mar 24 | F8: 25000
A9: repayment | E9: 18th Mar 24 | F9: 25000
A10: repayment | E10: 27th Mar 24 | F10: 25000
A11: repayment | E11: 28th Mar 24 | F11: 25000
E12: March month | F12: skip
E13: April Month | F13: Not paid
E14: May Month | F14: Not paid
H18: capital returned | J18: 3% intrest to be
D19: =SUM(D2:D4) -> 500000 | F19: =SUM(F2:F11) -> 250000 | H19: =F19/D19 -> 0.5 | J19: =(D19-F19)*3/100 -> 7500 | K19: June end
J20: =J19 -> 7500 | K20: July end
J21: =J20 -> 7500 | K21: August end
D24: IN CASE OF DISCONTINUE FROM INVESTMENT CAPITAL WILL START REPAYMENT FROM END OF SEPTEMBER 24
D28: Capital Invested | E28: % of returns capital | F28: month of used of capital | H28: per month min intrest | I28: total intrest for the month your funds is being used by us
D29: =D19 -> 500000 | E29: 3 | F29: 5 | H29: =D29*E29/100 -> 15000 | I29: =H29*F29 -> 75000
I34: =D29+I29 -> 575000
H36: REPAYMENT TILL NOW WE MADE | I36: =F19 -> 250000
H38: YOU WILL NEED TO REPAY US BACK TO DISCONTINUE WITH PLANS | I38: =I34-I36 -> 325000 | K38: Repayment will start from September 24 end
K39: =I38/3 -> 108333.33 | L39: Sep end
K40: =K39 -> 108333.33 | L40: Oct end
K41: =K40 -> 108333.33 | L41: Nov end

Sheet Deepak Rajpoot
A1: Transaction types | B1: date of investment | C1: agreement name | D1: amount of investment | E1: repayment dates | F1: repayment amount | J1: ROI
A2: investment | B2: 31th may 23 | C2: Deepak Rajpoot | D2: 50000 | J2: 0.2
A3: repayment | E3: 30th june 23 | F3: 10000
A4: repayment | E4: 1st aug 23 | F4: 10000 | J4: 0.32
A5: investment | B5: 7th Aug 23 | C5: Deepak Rajpoot | D5: 100000 | E5: 31st Aug 23 | F5: 32000
A6: investment | B6: 24th Oct 23 | C6: Deepak Rajpoot | D6: 50000 | E6: 30th sep 23 | F6: 32000 | J6: 0.3
A7: investment | B7: 03rd April 23 | C7: Deepak Rajpoot | D7: 100000 | E7: 1st Nov 23 | F7: 32000 | J7: 0.15
A8: investment | B8: 30th March 23 | C8: Deepak Rajpoot | D8: 100000 | E8: 1st Dec 23 | F8: 32000 | J8: 15
A9: repayment | E9: 4th dec 23 | F9: 15000
A10: repayment | E10: 4tj jan 24 | F10: 47000
A11: repayment | E11: 3rd Feb 24 | F11: 47000
A12: repayment | E12: 6th mar 24 | F12: 25000
A13: repayment | E13: 7th mar 24 | F13: 22000
A14: repayment | E14: 3rd May 24 | F14: 22000
A15: repayment | E15: 7th May 24 | F15: 40000
A16: repayment | E16: 5th July 24 | F16: 20000
H20: capital returned | J20: 5% returns for june july and aug
D21: =SUM(D2:D18) -> 400000 | F21: =SUM(F2:F18) -> 386000 | H21: =F21/D21 -> 0.965 | J21: =(D21)*5/100 -> 20000
J22: =J21 -> 20000
J23: =J22 -> 20000
D24: IN CASE OF DISCONTINUE FROM INVESTMENT CAPITAL WILL START REPAYMENT FROM END OF SEPTEMBER 24
D28: Capital Invested | E28: % of returns capital | F28: month of used of capital | H28: per month min intrest | I28: total intrest for the month your funds is being used by us
D29: =D2 -> 50000 | F29: 13 | H29: =D29*E29/100 -> 0 | I29: =H29*F29+D29 -> 50000
D30: =D5 -> 100000 | F30: 9 | H30: =D30*E30/100 -> 0 | I30: =H30*F30+D30 -> 100000
D31: =D6 -> 50000 | F31: 9 | H31: =D31*E31/100 -> 0 | I31: =H31*F31+D31 -> 50000
D32: =D7 -> 100000 | F32: 15 | H32: =D32*E32/100 -> 0 | I32: =H32*F32+D32 -> 100000
D33: =D8 -> 100000 | F33: 15 | H33: =D33*E33/100 -> 0 | I33: =H33*F33+D33 -> 100000
I34: =SUM(I29:I33) -> 400000
H36: REPAYMENT TILL NOW WE MADE | I36: =F21 -> 386000
H38: YOU WILL NEED TO REPAY US BACK TO DISCONTINUE WITH PLANS | I38: =I34-I36 -> 14000 | K38: Repayment will start from September 24 end
K39: =I38/3 -> 4666.6667 | L39: Sep end
K40: =K39 -> 4666.6667 | L40: Oct end
K41: =K40 -> 4666.6667 | L41: Nov end

Sheet sujata krishnamurthi
A1: Transaction types | B1: date of investment | C1: agreement name | D1: amount of investment | E1: repayment dates | F1: repayment amount | J1: ROI
A2: investment | B2: 09th June 23 | C2: Sujata krishnamurthi | D2: 25000 | J2: 0.3
A3: investment | B3: 10th June 23 | C3: Sujata krishnamurthi | D3: 15000 | J3: 0.3
A4: investment | B4: 10th June 23 | C4: Sujata krishnamurthi | D4: 60000 | J4: 0.3
A5: repayment | E5: 30th june 23 | F5: 20000
A6: repayment | E6: 1st July 23 | F6: 20000
A7: investment | B7: 15th July 24 | C7: Sujata krishnamurthi | D7: 100000 | J7: 0.32
A8: repayment | E8: 1st Aug 23 | F8: 16000
A9: repayment | E9: 1st Sep 23 | F9: 32000
A10: repayment | E10: 1st Oct 23 | F10: 62000
A11: repayment | E11: 3rd Nov 23 | F11: 30000
A12: repayment | E12: 3rd Nov 23 | F12: 32000
A13: investment | B13: 25th Nov 23 | C13: Sujata krishnamurthi | D13: 100000 | E13: 25th nov 23 | F13: 32000 | G13: addjusted to the investment of 2L of sujata krishnamurth
A14: repayment | E14: 25th nov 23 | F14: 30000 | G14: addjusted to the investment of 2L of sujata krishnamurth
A15: repayment | E15: 3rd Jan 24 | F15: 30000
A16: repayment | E16: 8th Jan 24 | F16: 25000
A17: repayment | E17: 10th Feb 24 | F17: 30000
H19: capital returned
D20: =SUM(D2:D18) -> 300000 | F20: =SUM(F2:F18) -> 359000 | H20: =F20/D20 -> 1.1966667
C21: Jannesh krishnamurthi | D21: ='Jannesh krishnamurthi'!D36 -> 75000 | F21: ='Jannesh krishnamurthi'!F36 -> 689875 | H21: =F21/D21 -> 9.1983333
C22: somaya Bg | D22: ='Somaya Bg'!D16 -> 400000 | F22: ='Somaya Bg'!F16 -> 340000 | H22: =F22/D22 -> 0.85
D24: =SUM(D20:D22) -> 775000 | F24: =SUM(F20:F22) -> 1388875 | H24: =F24/D24 -> 1.7920968

Sheet Jannesh krishnamurthi
A1: Transaction types | B1: date of investment | C1: agreement name | D1: amount of investment | E1: repayment dates | F1: repayment amount | J1: ROI
A2: investment | B2: 15th April 24 | C2: Jannesh Krishnamurthi | D2: 25000 | J2: 0.35
A3: investment | B3: 29th May 24 | C3: Jannesh Krishnamurthi | D3: 50000 | J3: 0.3 | K3: =D3*J3 -> 15000
A4: repayment | E4: 05th May 23 | F4: 4375
A5: repayment | E5: 31st May 23 | F5: 8750
A6: repayment | E6: 30th june 23 | F6: 8750
A7: repayment | E7: 30th june 23 | F7: 15000
A8: repayment | E8: 1st Aug 23 | F8: 30000
A9: repayment | E9: 31st Aug 23 | F9: 30000
A10: repayment | E10: 1st Sep 23 | F10: 15000
A11: repayment | E11: 1st Sep 23 | F11: 8750
A12: repayment | E12: 30th sep 23 | F12: 23750
A13: repayment | E13: 1st Oct 23 | F13: 0 | G13: 60000 | H13: for somaya Bg
A14: Bonus | E14: 5th oct 23 | F14: 3000
A15: repayment | E15: 3rd nov 23 | F15: 23750
A16: repayment | E16: 25th nov 23 | F16: 8750 | G16: Addjusted to the investment of 2L of sujata krishnamurth
A17: repayment | E17: 25th nov 23 | F17: 15000 | G17: Addjusted to the investment of 2L of sujata krishnamurth
A18: Bonus | E18: 10th Dec 23 | F18: 6000
A19: repayment | E19: 3rd Jan 24 | F19: 23750
A20: repayment | E20: 7th Jan 24 | F20: 30000
A21: repayment | E21: 2nd Feb 24 | F21: 53750
A22: repayment | E22: 10th Mar 24 | F22: 25000
A23: repayment | E23: 16th Mar 24 | F23: 25000
A24: repayment | E24: 20th Mar 24 | F24: 20000
A25: repayment | E25: 26th Mar 24 | F25: 20000
A26: repayment | E26: 28th Mar 24 | F26: 100000
A27: repayment | E27: 1st April 24 | F27: 115750
A28: Bonus | E28: 11th April 24 | F28: 22000
A29: repayment | E29: 2nd May 24 | F29: 23750
A30: repayment | E30: 7th May 24 | F30: 30000
H35: Capital Returned
D36: =SUM(D2:D30) -> 75000 | F36: =SUM(F2:F30) -> 689875 | H36: =F36/D36 -> 9.1983333

Sheet Somaya Bg
A1: Transaction types | B1: date of investment | C1: agreement name | D1: amount of investment | E1: repayment dates | F1: repayment amount
A2: investment | B2: 31st august | C2: somaya bg | D2: 100000
A3: investment | B3: 31st august | C3: somaya bg | D3: 100000
A4: repayment | E4: 1st oct 23 | F4: 60000 | G4: transfered to jannesh account
E5: 1st Nov 23 | F5: 60000
E6: 25th nov 23 | F6: 60000 | G6: addjusted to the investment of 2L of sujata krishnamurth
A7: investment | B7: 25th Nov 23 | C7: somaya bg | D7: 200000
E8: 5th Jan 24 | F8: 60000
E9: 10th Jan 24 | F9: 50000
E10: 10th Feb 24 | F10: 50000
H15: capital returned
D16: =SUM(D2:D7) -> 400000 | F16: =SUM(F3:F10) -> 340000 | H16: =F16/D16 -> 0.85

Sheet Yogansh Sony 
A1: Transaction types | B1: date of investment | C1: agreement name | D1: amount of investment | E1: repayment dates | F1: repayment amount
A2: Investment | B2: 10th Feb 24 | C2: 100000
C3: 50000
C4: 25000
C5: 25000
A6: investment | B6: 1st June 2024 | C6: 30000
E7: 5th July 2024 | F7: 41400
E8: 7th June 2024 | F8: 36000
E9: 5th March 2024. | F9: 22800
C13: =sum(C2:C11) -> 230000 | F13: =sum(F7:F10) -> 100200 | H13: =C13-F13 -> 129800

Sheet moxit Takor
A1: Transaction types | B1: date of investment | C1: agreement name | D1: amount of investment | E1: repayment dates | F1: repayment amount | J1: ROI
A2: investment | B2: 05th June 23 | C2: Moxit Takor | D2: 25000 | J2: 12
A3: repayment | E3: 31st May 23 | F3: 3000
A4: investment | B4: 10th june 23 | C4: Moxit Takor | D4: 100000 | J4: 30
A5: repayment | E5: 30th June 23 | F5: 20000
A6: repayment | E6: 30th June 23 | F6: 3000
A7: repayment | E7: 1st Aug 23 | F7: 3000
A8: repayment | E8: 1st Aug 23 | F8: 30000
A9: repayment | E9: 31st aug 23 | F9: 30000
A10: repayment | E10: 31st aug 23 | F10: 3000
A11: repayment | E11: 30th sep 23 | F11: 33000
A12: repayment | E12: 3rd nov 23 | F12: 33000
A13: repayment | E13: 30th nov 23 | F13: 33000
A14: repayment | E14: 9th Jan 24 | F14: 33000
A15: repayment | E15: 2nd Feb 24 | F15: 33000
A16: repayment | E16: 12th Mar 24 | F16: 25000
A17: repayment | E17: 28th Mar 24 | F17: 8000
H20: capital returned
A21: Moxit Takor | D21: =SUM(D2:D19) -> 125000 | F21: =SUM(F2:F19) -> 290000 | H21: =F21/D21 -> 2.32 | J21: =D21*3/100 -> 3750
A22: Nikitaben | D22: ='nikitaben solanki'!D17 -> 100000 | F22: ='nikitaben solanki'!F17 -> 234000 | H22: =F22/D22 -> 2.34 | J22: =D22*3/100 -> 3000
A23: Tarunaben | D23: ='Tarunaben solanki'!D14 -> 100000 | F23: ='Tarunaben solanki'!F14 -> 45000 | H23: =F23/D23 -> 0.45 | J23: =D23*3/100 -> 3000
D25: =SUM(D21:D23) -> 325000 | F25: =SUM(F21:F23) -> 569000 | H25: =F25/D25 -> 1.7507692

Sheet nikitaben solanki
A1: Transaction types | B1: date of investment | C1: agreement name | D1: amount of investment | E1: repayment dates | F1: repayment amount | J1: Roi
A2: investment | B2: 21st July | C2: Nikitaben Solanki | D2: 100000 | J2: 32
E3: 1st Aug 23 | F3: 9600
E4: 1st Aug 23 | F4: 400
E5: 1st Sep 23 | F5: 32000
E6: 1st oct 23 | F6: 32000
E7: 3rd nov 23 | F7: 5000
E8: 5th nov 23 | F8: 27000
E9: 30th nov 23 | F9: 32000
E10: 9th Jan 24 | F10: 32000
E11: 2nd Feb 24 | F11: 32000
E12: 28th Mar 24 | F12: 32000
H16: capital returned
D17: =SUM(D2:D14) -> 100000 | F17: =SUM(F2:F16) -> 234000 | H17: =F17/D17 -> 2.34

Sheet Tarunaben solanki
A1: Transaction types | B1: date of investment | C1: agreement name | D1: amount of investment | E1: repayment dates | F1: repayment amount | J1: Roi
A2: Investment | B2: 7th dec 23 | C2: tarunaben solanki | D2: 100000
E3: 9th jan 24 | F3: 15000
E4: 2nd Feb 24 | F4: 15000
E5: 28th Mar 24 | F5: 15000
H13: capital returned
D14: =SUM(D2:D12) -> 100000 | F14: =SUM(F2:F12) -> 45000 | H14: =F14/D14 -> 0.45

Sheet kala arudara jaykar
A1: Transaction types | B1: date of investment | C1: agreement name | D1: amount of investment | E1: repayment dates | F1: repayment amount | J1: ROI
A2: Investment | B2: 01st July 23 | C2: Kala Radhika R | D2: 100000 | J2: 0.3
E3: 1st Aug 23 | F3: 30000
A4: Investment | B4: 31st Aug 23 | C4: Kala Radhika R | D4: 200000 | J4: 0.3
E5: 1st sep 23 | F5: 30000
E6: 30th sep 23 | F6: 30000
E7: 2nd oct 23 | F7: 60000
E8: 3rd nov 23 | F8: 60000
E9: 5th nov 23 | F9: 30000
E10: 4th dec 23 | F10: 30000
E11: 7th dec 23 | F11: 60000
E12: 8th jan 24 | F12: 30000
E13: 8th jan 24 | F13: 60000
E14: 10th feb 24 | F14: 30000
E15: 18th mar 24 | F15: 25000
E16: 1st april 24 | F16: 80000
H20: capital returned
D21: =SUM(D2:D18) -> 300000 | F21: =SUM(F3:F17) -> 555000 | H21: =F21/D21 -> 1.85

Sheet monojkumar modi
A1: Transaction types | B1: date of investment | C1: agreement name | D1: amount of investment | E1: repayment dates | F1: repayment amount | J1: ROI
A2: Investment | B2: 3rd Feb 2024 | C2: Manoj kumar Modi | D2: 100000 | J2: 0.12
A3: repayment | E3: 05th March 24 | F3: 12000
A4: Investment | B4: 14th Mar 2024 | D4: 500000 | J4: 0.3 | L4: =D4*30/100 -> 150000
E5: 5th April 24 | F5: 80000 | L5: =L4/30 -> 5000
E6: 6th April 24 | F6: 12000 | L6: =L5*15 -> 75000
H9: capital returned | J9: 5% returns for june july and aug
D10: =SUM(D2:D8) -> 600000 | F10: =SUM(F2:F8) -> 104000 | H10: =F10/D10 -> 0.17333333 | J10: =(D10-F10)*5/100 -> 24800
J11: =J10 -> 24800
D12: 600000 | E12: =D12*5/100 -> 30000 | J12: =J11 -> 24800
D15: IN CASE OF DISCONTINUE FROM INVESTMENT CAPITAL WILL START REPAYMENT FROM END OF SEPTEMBER 24
E17: INVESTMENT OF | F17: MIN RETURNS | G17: USED MONTHS | I17: PER MOTH INTREST | J17: TOTAL INTREST TILL DATE ON INVESTMENT | K17: TOTAL AMOUNT TO REPAY
D18: 1st investment | E18: 100000 | F18: 3 | G18: 4 | I18: =E18*F18/100 -> 3000 | J18: =I18*G18 -> 12000 | K18: =E18+J18 -> 112000
D19: 2nd Investment | E19: 500000 | F19: 3 | G19: 2.5 | I19: =E19*F19/100 -> 15000 | J19: =I19*G19 -> 37500 | K19: =E19+J19 -> 537500
K22: =SUM(K18:K20) -> 649500
I24: REPAYMENT TILL NOW WE MADE | K24: =F10 -> 104000
I26: YOU WILL NEED TO REPAY US BACK TO DISCONTINUE WITH PLANS | K26: =K22-K24 -> 545500
H28: 45559 | I28: 1 | K28: =K26/3 -> 181833.33
H29: 45589 | I29: 2 | K29: =K26/3 -> 181833.33
H30: 45620 | I30: 3 | K30: =K26/3 -> 181833.33

Sheet surendraSarangi
A1: Transaction types | B1: date of investment | C1: agreement name | D1: amount of investment | E1: repayment dates | F1: repayment amount | J1: ROI
A2: Investment | B2: 30th Sep 23 | C2: Surendra Sarangi | D2: 500000 | J2: 0.25 | L2: =D2*J2 -> 125000
A3: Repayment | E3: 5th Nov 23 | F3: 125000
E4: 1st Dec 23 | F4: 125000
E5: 4th Jan 24 | F5: 125000
A6: investment | B6: 10th Jan 23 | C6: Surendra Sarangi | D6: 500000 | J6: 0.25
E7: 4th feb 24 | F7: 125000
E8: 30th March 24 | F8: 83333
E9: 1st April 24 | F9: 125000
E10: 28th April 24 | F10: 125000
H16: capital returned | J16: 5% returns for june july and aug
D17: =SUM(D2:D14) -> 1000000 | F17: =SUM(F2:F14) -> 833333 | H17: =F17/D17 -> 0.833333 | J17: =(D17-F17)*5/100 -> 8333.35
H18: =D17-F17 -> 166667 | J18: =J17 -> 8333.35
J19: =J18 -> 8333.35

Sheet Mousami Rath
A1: Transaction types | B1: date of investment | C1: agreement name | D1: amount of investment | E1: repayment dates | F1: repayment amount | J1: ROI
A2: Investment | B2: 21st July | C2: Mousami Rath | D2: 100000 | J2: 0.15
A3: Repayment | E3: 1st Aug 23 | F3: 5000
A4: Repayment | E4: 1st Sep 23 | F4: 15000
A5: Repayment | E5: 30th Sep 23 | F5: 15000
A6: Repayment | E6: 31st sep 23 | F6: 15000
A7: bonus | E7: 6th Nov 23 | F7: 8750
A8: Repayment | E8: 6th Dec 23 | F8: 15000
A9: bonus | E9: 10th Dec | F9: 8750
A10: Repayment | E10: 2nd Jan 24 | F10: 15000
A11: bonus | E11: 18th Jan 24 | F11: 8750
A12: Repayment | E12: 4th Feb 24 | F12: 15000
A13: Repayment | E13: 28th Mar 24 | F13: 15000
H18: capital returned | J18: 5% returns for june july and aug
D19: =SUM(D2:D14) -> 100000 | F19: =SUM(F4:F16) -> 131250 | H19: =F19/D19 -> 1.3125 | J19: =(D19*5/100) -> 5000
J20: =J19 -> 5000
J21: =J20 -> 5000

Sheet nirdesh Thakur
A1: Transaction types | B1: date of investment | C1: agreement name | D1: amount of investment | E1: repayment dates | F1: repayment amount | J1: ROI
A2: Investment | B2: 03rd July 23 | C2: Nirdesh Thakur | D2: 25000 | J2: 0.15
A3: investment | B3: 15th Aug 23 | C3: Nirdesh Thakur | D3: 100000 | J3: 0.15
A4: Repayment | E4: 31st Aug 23 | F4: 3125
A5: Repayment | E5: 31st Aug 23 | F5: 15000
A6: Repayment | E6: 30th Sep 23 | F6: 18125
A7: Repayment | E7: 1st Nov 23 | F7: 18125
A8: investment | B8: 21st nov 23 | C8: Nirdesh Thakur | D8: 25000 | J8: 0.1
A9: repayment | E9: 4th dec 23 | F9: 18500
A10: repayment | E10: 4th Jan 24 | F10: 21875
A11: investment | B11: 07th Jan 24 | C11: Nirdesh Thakur | D11: 50000
E12: 8th feb 24 | F12: 26875
E13: 12th Mar 24 | F13: 1875
A14: investment | B14: 29th Mar 4 | C14: Nirdesh Thakur | D14: 50000
E15: 8th May 24 | F15: 31875
H18: capital returned | J18: 5% returns for june july and aug
D19: =SUM(D2:D14) -> 250000 | F19: =SUM(F2:F16) -> 155375 | H19: =F19/D19 -> 0.6215 | J19: =(D19-F19)*5/100 -> 4731.25
J20: 4731.25
J21: 4731.25
D24: IN CASE OF DISCONTINUE FROM INVESTMENT CAPITAL WILL START REPAYMENT FROM END OF SEPTEMBER 24
D27: capital | E27: % of returns capital | F27: month of used of capital | H27: per month min intrest | I27: total intrest for the month your funds is being used by us
D28: 125000 | E28: 3 | F28: 8 | H28: =D28*E28/100 -> 3750 | I28: =F28*H28 -> 30000
D29: 50000 | E29: 3 | F29: 5 | H29: =D29*E29/100 -> 1500 | I29: =F29*H29 -> 7500
D30: 50000 | E30: 3 | F30: 3 | H30: =D30*E30/100 -> 1500 | I30: =F30*H30 -> 4500
D31: 50000 | E31: 3 | F31: 2 | H31: =D31*E31/100 -> 1500 | I31: =F31*H31 -> 3000
D33: =SUM(D28:D31) -> 275000 | I33: =SUM(I28:I31) -> 45000 | K33: =SUM(D33:I33) -> 320000
J34: till now the repayment done | K34: =F19 -> 155375
K36: =K33-K34 -> 164625
J37: augus | K37: =K36/3 -> 54875
J38: sep | K38: =K36/3 -> 54875
J39: oct | K39: =K36/3 -> 54875

Sheet joti shankar mishra
A1: Transaction types | B1: date of investment | C1: agreement name | D1: amount of investment | E1: repayment dates | F1: repayment amount | J1: ROI
A2: Investment | B2: 08th March 24 | C2: Jyoti shankar Mishra | D2: 50000 | J2: 0.25
A3: Investment | B3: 12th March 24 | C3: Jyoti shankar Mishra | D3: 400000 | J3: 0.25
A4: repayment | E4: 5th April 24 | F4: 71250
A5: Investment | B5: 25th April 24 | D5: 560000 | J5: 0.3
A6: Investment | B6: 25th April 24 | D6: 90000 | J6: 0.3 | K6: on total investment amount on 11 lakhs
A7: repayment | E7: 7th May 24 | F7: 50000
A8: repayment | E8: 8th May 24 | F8: 95000
H13: capital returned
D14: =SUM(D2:D11) -> 1100000 | F14: =SUM(F2:F11) -> 216250 | H14: =F14/D14 -> 0.19659091 | I14: june | J14: =(D14-F14)*5/100 -> 44187.5
I15: july | J15: =J14 -> 44187.5
I16: aug | J16: =J15 -> 44187.5

Sheet Hemendra srivastava
A1: Transaction types | B1: date of investment | C1: agreement name | D1: amount of investment | E1: repayment dates | F1: repayment amount | J1: ROI
A2: Investment | B2: 11th Aug 2023 | C2: Hemendra srivastava | D2: 50000 | H2: 45509 | J2: 0.3 | L2: 20
A3: Investment | B3: 12th Aug 2023 | C3: Hemendra srivastava | D3: 450000 | H3: 45509 | J3: 0.3
E4: 1st Sep 23 | F4: 100000
E5: 30th sep 23 | F5: 150000
A6: investment | B6: 30th Sep 23 | C6: Hemendra srivastava | D6: 100000 | H6: 45509 | J6: 0.25
A7: investment | B7: 4th Oct 23 | C7: Hemendra srivastava | D7: 400000 | H7: 45509 | J7: 0.25
E8: 31st Oct 23 | F8: 150000
E9: 4th nov 23 | F9: 105000
E10: 4th dec 23 | F10: 150000
E11: 6th dec 23 | F11: 125000
E12: 30th dec 23 | F12: 125000
E13: 10th jan 24 | F13: 150000
E14: 9th Mar 24 | F14: 25000
E15: 18th mar 24 | F15: 25000
E16: 20th mar 24 | F16: 20000
E17: 27th mar 24 | F17: 80000
E18: 30th mar 24 | F18: 200000
E19: 1st April 24 | F19: 200000
... E21: 7th may 24 | F21: 150000
A22: investment | B22: 7th May 24 | C22: Hemendra srivastava | D22: 150000 | H22: 45509 | J22: 0.3
A23: investment | B23: 7th May 24 | C23: Hemendra srivastava | D23: 450000 | H23: 45509 | J23: 0.3
H27: capital returned
D28: =SUM(D2:D25) -> 1600000 | F28: =SUM(F2:F25) -> 1880000 | H28: =F28/D28 -> 1.175
C32: DISCONTINUE FROM INVESTMENT CAPITAL WILL START REPAYMENT FROM END OF SEPTEMBER 24
D34: INVESTMENT OF | E34: MIN RETURNS @ 3% | F34: USED MONTHS | H34: PER MOTH INTREST | I34: TOTAL INTREST TILL DATE ON INVESTMENT | J34: TOTAL AMOUNT TO REPAY
C35: 1st investment | D35: 500000 | E35: 3 | F35: 12 | H35: =D35*E35/100 -> 15000 | I35: =H35*F35 -> 180000 | J35: =D35+I35 -> 680000
C36: 2nd Investment | D36: 500000 | E36: 3 | F36: 10 | H36: =D36*E36/100 -> 15000 | I36: =H36*F36 -> 150000 | J36: =D36+I36 -> 650000
C37: 3rd Investment | D37: 600000 | E37: 3 | F37: 3 | H37: =D37*E37/100 -> 18000 | I37: =H37*F37 -> 54000 | J37: =D37+I37 -> 654000
J39: =SUM(J35:J37) -> 1984000
H41: REPAYMENT TILL NOW WE MADE | J41: =F28 -> 1880000
H43: YOU WILL NEED TO REPAY US BACK TO DISCONTINUE WITH PLANS | J43: =J39-J41 -> 104000 | L43: Repayment will start from September 24 end
L44: =J43/3 -> 34666.667 | M44: 5th Oct 24
L45: =L44 -> 34666.667 | M45: 5th Nov 24
L46: =L45 -> 34666.667 | M46: 5th Dec 24

Sheet Vinayak Chavhan
A1: Transaction types | B1: date of investment | C1: agreement name | D1: amount of investment | E1: repayment dates | F1: repayment amount | J1: ROI
A2: Investment | B2: 18th June 23 | C2: Vinayak Chavhan | D2: 50000 | J2: 0.3
A3: Repayment | E3: 30th June 23 | F3: 2708
A4: Investment | B4: 03rd July 23 | C4: Vinayak Chavhan | D4: 50000
A5: Investment | B5: 01st August 23 | C5: Vinayak Chavhan | D5: 200000
A6: Investment | B6: 01st August 23 | C6: Vinayak Chavhan | D6: 25000
A7: Investment | B7: 01st August 23 | C7: Vinayak Chavhan | D7: 95000
A8: Investment | B8: 02nd August 23 | C8: Vinayak Chavhan | D8: 80000

Sheet kush bansal
A1: Transaction types | B1: date of investment | C1: agreement name | D1: amount of investment | E1: repayment dates | F1: repayment amount | J1: ROI
A2: Investment | B2: 27th June 23 | C2: Kush Bansal | D2: 100000 | J2: 0.3
A3: Repayment | E3: 31st july 2023 | F3: 30000
A4: Repayment | E4: 31st Aug 2023 | F4: 30000
A5: Investment | B5: 05th september 23 | D5: 100000
A6: Repayment | E6: 30th Sep 23 | F6: 30000
A7: Repayment | E7: 01st Oct 23 | F7: 24000
A8: Repayment | E8: 01st Oct 23 | F8: 30000
A9: bonus | E9: 05th oct 23 | F9: 1200
A10: Repayment | E10: 31st Oct 23 | F10: 30000
A11: Repayment | E11: 5th Nov 23 | F11: 30000
A12: Bonus | E12: 6th nov 23 | F12: 3000
A13: Repayment | E13: 09th Dec 23 | F13: 60000
A14: bonus | E14: 10th Dec 23 | F14: 3000
A15: Repayment | E15: 10th Jan 23 | F15: 60000
E16: 27th april | F16: 30000
E18: 45405
E19: 45435
J23: 3% intrest to be
D24: =SUM(D2:D20) -> 200000 | F24: =SUM(F2:F20) -> 361200 | H24: =F24/D24 -> 1.806 | J24: =D24*3/100 -> 6000
J25: =J24 -> 6000
J26: =J25 -> 6000
D29: IN CASE OF DISCONTINUE FROM INVESTMENT CAPITAL WILL START REPAYMENT FROM END OF SEPTEMBER 24
E31: INVESTMENT OF | F31: MIN RETURNS | G31: USED MONTHS | I31: PER MOTH INTREST | J31: TOTAL INTREST TILL DATE ON INVESTMENT | K31: TOTAL AMOUNT TO REPAY
D32: 1st investment | E32: 100000 | F32: 3 | G32: 10 | I32: =E32*F32/100 -> 3000 | J32: =I32*G32 -> 30000 | K32: =E32+J32 -> 130000
D33: 2nd Investment | E33: 100000 | F33: 3 | G33: 8 | I33: =E33*F33/100 -> 3000 | J33: =I33*G33 -> 24000 | K33: =E33+J33 -> 124000
K36: =SUM(K32:K34) -> 254000
I38: REPAYMENT TILL NOW WE MADE | K38: =F24 -> 361200
I40: YOU WILL NEED TO REPAY US BACK TO DISCONTINUE WITH PLANS | K40: =K36-K38 -> -107200 | M40: Repayment till September 24 end

Sheet Meenu Bhagarita
A1: Transaction types | B1: date of investment | C1: agreement name | D1: amount of investment | E1: repayment dates | F1: repayment amount | J1: ROI
A2: Investment | B2: 29th Nov 23 | C2: Meenu Bhagarita | D2: 100000 | J2: 0.1
A3: Repayment | E3: 31st dec 23 | F3: 10000
A4: Repayment | E4: 2nd Feb 24 | F4: 10000
A5: Repayment | E5: 05th Mar 24 | F5: 10000
A6: Repayment | E6: 7th Apri 24 | F6: 10000
A7: Repayment | E7: 8th May 24 | F7: 10000
L13: 1.5% intrest on pending capital
D14: =SUM(D2:D10) -> 100000 | F14: =SUM(F2:F10) -> 50000 | H14: =F14/D14 -> 0.5 | L14: =(D14-F14)*1.5/100 -> 750
L15: =L14 -> 750
L16: =L15 -> 750
D19: IN CASE OF DISCONTINUE FROM INVESTMENT CAPITAL WILL START REPAYMENT FROM END OF SEPTEMBER 24
E21: INVESTMENT OF | F21: MIN RETURNS | G21: USED MONTHS | I21: PER MOTH INTREST | J21: TOTAL INTREST TILL DATE ON INVESTMENT | K21: TOTAL AMOUNT TO REPAY
D22: 1st investment | E22: =D14 -> 100000 | F22: 1.5 | G22: 13 | I22: =E22*F22/100 -> 1500 | J22: =I22*G22 -> 19500 | K22: =E22+J22 -> 119500
K26: =SUM(K22:K24) -> 119500
H29: REPAYMENT TILL NOW WE MADE | J29: =E15 | K29: =F14 -> 50000
H31: YOU WILL NEED TO REPAY US BACK TO DISCONTINUE WITH PLANS | K31: =K26-K29 -> 69500

Sheet Meena sir Faang investment
A1: Transaction types | B1: date of investment | C1: agreement name | D1: amount of investment | E1: repayment dates | F1: repayment amount | J1: ROI
A2: Investment | B2: 19th Sep 23 | C2: Meena sir | D2: 200000 | J2: 0.3
A3: Repayment | E3: 1st oct 23 | F3: 24000
A4: Repayment | E4: 5th Nov 23 | F4: 60000
A5: Repayment | E5: 9th Dec 23 | F5: 60000
A6: Repayment | E6: 11th Jan 24 | F6: 60000
A7: Repayment | E7: 05Th feb 24 | F7: 0 | G7: 60000 | H7: pending
E8: 45375 | G8: 0 | H8: Skiped
E9: 27th april 24 | F9: 60000
E10: 45436 | G10: 60000 | H10: pending
H13: capital returned | J13: 5% intrest to be
D14: =SUM(D2:D10) -> 200000 | F14: =SUM(F2:F10) -> 264000 | H14: =F14/D14 -> 1.32 | J14: =(D14)*5/100 -> 10000 | K14: June end
J15: =J14 -> 10000 | K15: July Edn
J16: =J15 -> 10000 | K16: August end
D19: IN CASE OF DISCONTINUE FROM INVESTMENT CAPITAL WILL START REPAYMENT FROM END OF SEPTEMBER 24
E21: INVESTMENT OF | F21: MIN RETURNS | G21: USED MONTHS | I21: PER MOTH INTREST | J21: TOTAL INTREST TILL DATE ON INVESTMENT | K21: TOTAL AMOUNT TO REPAY
D22: 1st investment | E22: 200000 | F22: 3 | G22: 7 | I22: =E22*F22/100 -> 6000 | J22: =I22*G22 -> 42000 | K22: =E22+J22 -> 242000
K26: =SUM(K22:K24) -> 242000
I28: REPAYMENT TILL NOW WE MADE | K28: =F14 -> 264000
I30: YOU WILL NEED TO REPAY US BACK TO DISCONTINUE WITH PLANS | K30: =K26-K28 -> -22000 | M30: Repayment till September 24 end
M31: =K30/3 -> -7333.3333 | N31: Sep end
M32: =M31 -> -7333.3333 | N32: Oct end
M33: =M32 -> -7333.3333 | N33: Nov end

Sheet Trupti jadeja
A1: Transaction types | B1: date of investment | C1: agreement name | D1: amount of investment | E1: repayment dates | F1: repayment amount | J1: ROI
A2: Investment | B2: 16th aug 23 | C2: Trupti jadeja | D2: 50000 | J2: 0.12
A3: repayment | E3: 30th sep 23 | F3: 6000
E4: 31st Oct 23 | F4: 6000
E5: 30th Nov 23 | F5: 6000
E6: 1st Jan 24 | F6: 6000
E7: 6th Feb 24 | F7: 6000
B8: 20th feb 24 | C8: Trupti jadeja | D8: 50000 | J8: 0.12
E9: 6th March 24 | F9: 7616
E10: 7th April 24 | F10: 11000
E11: 7th May 24 | F11: 11000
H17: capital returned | J17: 5% intrest to be
D18: =SUM(D1:D16) -> 100000 | F18: =SUM(F1:F16) -> 59616 | H18: =F18/D18 -> 0.59616 | J18: =(D18-F18)*5/100 -> 2019.2 | K18: June end
J19: =J18 -> 2019.2 | K19: July Edn
J20: =J19 -> 2019.2 | K20: August end
D26: IN CASE OF DISCONTINUE FROM INVESTMENT CAPITAL WILL START REPAYMENT FROM END OF SEPTEMBER 24
E29: INVESTMENT OF | F29: MIN RETURNS | G29: USED MONTHS | I29: PER MOTH INTREST | J29: TOTAL INTREST TILL DATE ON INVESTMENT | K29: TOTAL AMOUNT TO REPAY
D30: 1st investment | E30: =D2 -> 50000 | F30: 3 | G30: 8 | I30: =E30*F30/100 -> 1500 | J30: =I30*G30 -> 12000 | K30: =E30+J30 -> 62000
D31: 2nd Investment | E31: =D8 -> 50000 | F31: 3 | G31: 3 | I31: =E31*F31/100 -> 1500 | J31: =I31*G31 -> 4500 | K31: =E31+J31 -> 54500
K34: =SUM(K30:K32) -> 116500
I36: REPAYMENT TILL NOW WE MADE | K36: =F18 -> 59616
I38: YOU WILL NEED TO REPAY US BACK TO DISCONTINUE WITH PLANS | K38: =K34-K36 -> 56884 | M38: Repayment will start from September 24 end
M39: =K38/3 -> 18961.333 | N39: Sep end
M40: =M39 -> 18961.333 | N40: Oct end
M41: =M40 -> 18961.333 | N41: Nov end

Sheet Ashok Sadariya
A1: Transaction types | B1: date of investment | C1: agreement name | D1: amount of investment | E1: repayment dates | F1: repayment amount | J1: ROI
A2: Investment | B2: 11th Nov 23 | C2: Ashok Sadariya | D2: 100000 | J2: 0.2
A3: Investment | B3: 26th Nov 23 | C3: Ashok Sadariya | D3: 200000 | J3: 21
A4: Investment | B4: 26th Nov 23 | C4: Ashok Sadariya | D4: 300000 | J4: 21
E5: 30th Nov 23 | F5: 14000
E6: 3rd Jan 24 | F6: 20000
E7: 5th Jan 24 | F7: 105000
E8: 7th Feb 24 | F8: 125000
A9: Investment | B9: 7th March 24 | C9: Ashok Sadariya | D9: 275000
D10: 125000 | E10: 7th March 24 | F10: 125000
H12: capital returned | J12: 5% intrest to be
D13: =SUM(D2:D12) -> 1000000 | F13: =SUM(F2:F10) -> 389000 | H13: =F13/D13 -> 0.389 | J13: =(D13)*5/100 -> 50000 | K13: June end
J14: =J13 -> 50000 | K14: July Edn
J15: =J14 -> 50000 | K15: August end
C19: IN CASE OF DISCONTINUE FROM INVESTMENT CAPITAL WILL START REPAYMENT FROM END OF SEPTEMBER 24
D21: INVESTMENT OF | E21: MIN RETURNS | F21: USED MONTHS | H21: PER MOTH INTREST | I21: TOTAL INTREST TILL DATE ON INVESTMENT | J21: TOTAL AMOUNT TO REPAY
C22: 1st investment | D22: =SUM(D2:D4) -> 600000 | E22: 3 | F22: 6.5 | H22: =D22*E22/100 -> 18000 | I22: =H22*F22 -> 117000 | J22: =D22+I22 -> 717000
C23: 2nd Investment | D23: =D9+F10 -> 400000 | E23: 3 | F23: 3 | H23: =D23*E23/100 -> 12000 | I23: =H23*F23 -> 36000 | J23: =D23+I23 -> 436000
J26: =SUM(J22:J24) -> 1153000
H28: REPAYMENT TILL NOW WE MADE | J28: =F13 -> 389000
H30: YOU WILL NEED TO REPAY US BACK TO DISCONTINUE WITH PLANS | J30: =J26-J28 -> 764000 | L30: Repayment will start from September 24 end
L31: =J30/3 -> 254666.67 | M31: Sep end
L32: =L31 -> 254666.67 | M32: Oct end
L33: =L32 -> 254666.67 | M33: Nov end

Sheet brijraj jadeja
A1: Transaction types | B1: date of investment | C1: agreement name | D1: amount of investment | E1: repayment dates | F1: repayment amount | J1: ROI
A2: Investment | B2: 31st May 23 | C2: Brijraj Jadeja | D2: 100000 | J2: 0.3
A3: repayment | E3: 30th june 23 | F3: 30000
A4: Investment | B4: 45129 | C4: Brijraj Jadeja | D4: 100000 | J4: 0.32
A5: repayment | E5: 3rd July 23 | F5: 30000
A6: repayment | E6: 1st Aug 23 | F6: 9600
A7: repayment | E7: 01st Aug 23 | F7: 30000
A8: repayment | E8: 31st Aug 23 | F8: 30000
A9: repayment | E9: 31st Aug 23 | F9: 25000
A10: repayment | E10: 1st Sep 23 | F10: 7000
A11: repayment | E11: 30th Sep 23 | F11: 32000
A12: repayment | E12: 30th Sep 23 | F12: 30000
A13: repayment | E13: 31st Oct 23 | F13: 32000
A14: repayment | E14: 3rd Nov 23 | F14: 30000
A15: repayment | E15: 30th Nov 23 | F15: 32000
A16: repayment | E16: 30th nov 23 | F16: 30000
... A19: repayment | E19: 04th Jan 24 | F19: 32000
H23: capital returned | J23: 3% intrest to be
D24: =SUM(D2:D20) -> 200000 | F24: =SUM(F2:F20) -> 439600 | H24: =F24/D24 -> 2.198 | K24: June end
K25: July End
K26: August end
C30: IN CASE OF DISCONTINUE FROM INVESTMENT CAPITAL WILL START REPAYMENT FROM END OF SEPTEMBER 24
D32: INVESTMENT OF | E32: MIN RETURNS | F32: USED MONTHS | H32: PER MOTH INTREST | I32: TOTAL INTREST TILL DATE ON INVESTMENT | J32: TOTAL AMOUNT TO REPAY
C33: 1st investment | D33: =D2 -> 100000 | E33: 3 | F33: 11 | H33: =D33*E33/100 -> 3000 | I33: =H33*F33 -> 33000 | J33: =D33+I33 -> 133000
C34: 2nd Investment | D34: =D4 -> 100000 | E34: 3 | F34: 9 | H34: =D34*E34/100 -> 3000 | I34: =H34*F34 -> 27000 | J34: =D34+I34 -> 127000
J37: =SUM(J33:J35) -> 260000
H39: REPAYMENT TILL NOW WE MADE | J39: =F24 -> 439600
H41: YOU WILL NEED TO REPAY US BACK TO DISCONTINUE WITH PLANS | J41: =J37-J39 -> -179600 | L41: Repayment will start from September 24 end
L42: =J41/3 -> -59866.667 | M42: Sep end
L43: =L42 -> -59866.667 | M43: Oct end
L44: =L43 -> -59866.667 | M44: Nov end

Sheet Meenu Bragta
A1: Transaction types | B1: date of investment | C1: agreement name | D1: amount of investment | E1: repayment dates | F1: repayment amount | J1: ROI
A2: Investment | B2: 29th Nov 23 | C2: Meenu Bragta | D2: 100000 | J2: 0.1
A3: repayment | E3: 31st Dec 23 | F3: 10000
A4: repayment | E4: 2nd Feb 24 | F4: 10000
A5: repayment | E5: 05th March 24 | F5: 10000
A6: repayment | E6: 7th April 24 | F6: 10000
A7: repayment | E7: 8th May 24 | F7: 10000
H20: capital returned | J20: 5% intrest to be
D21: =SUM(D2:D17) -> 100000 | F21: =SUM(F2:F17) -> 50000 | H21: =F21/D21 -> 0.5 | J21: =(D21-F21)*5/100 -> 2500 | K21: June end
J22: =J21 -> 2500 | K22: July end
J23: =J22 -> 2500 | K23: August end
C27: IN CASE OF DISCONTINUE FROM INVESTMENT CAPITAL WILL START REPAYMENT FROM END OF SEPTEMBER 24
D29: INVESTMENT OF | E29: MIN RETURNS | F29: USED MONTHS | H29: PER MOTH INTREST | I29: TOTAL INTREST TILL DATE ON INVESTMENT | J29: TOTAL AMOUNT TO REPAY
C30: 1st investment | D30: =D2 -> 100000 | E30: 3 | F30: 6 | H30: =D30*E30/100 -> 3000 | I30: =H30*F30 -> 18000 | J30: =D30+I30 -> 118000
J34: =SUM(J30:J32) -> 118000
H36: REPAYMENT TILL NOW WE MADE | J36: =F21 -> 50000
H38: YOU WILL NEED TO REPAY US BACK TO DISCONTINUE WITH PLANS | J38: =J34-J36 -> 68000 | L38: Repayment will start from September 24 end
L39: =J38/3 -> 22666.667 | M39: Sep end
L40: =L39 -> 22666.667 | M40: Oct end
L41: =L40 -> 22666.667 | M41: Nov end

Sheet Akshay Urade
A1: Transaction types | B1: date of investment | C1: Agreement name | D1: amount of investment | E1: repayment dates | F1: repayment amount
A2: Investment | B2: 30th sep 23 | C2: Akshay Urade | D2: 50000
B3: 01st Oct 23 | C3: Akshay Urade | D3: 95000
B4: 01st Oct 23 | C4: Akshay Urade | D4: 35000
B5: 01st Oct 23 | C5: Akshay Urade | D5: 20000
B6: 03st Oct 23 | C6: Akshay Urade | D6: 100000
B7: 03st Oct 23 | C7: Akshay Urade | D7: 100000
B8: 03st Oct 23 | C8: Akshay Urade | D8: 35000
B9: 03st Oct 23 | C9: Akshay Urade | D9: 25000
B10: 03st Oct 23 | C10: Akshay Urade | D10: 40000
E11: 3rd Nov 23 | F11: 125000
E12: 4th Dec 23 | F12: 125000
E13: 3th Jan 24 | F13: 125000
E14: 8th Feb 24 | F14: 125000
E15: 1st April 24 | F15: 125000
H18: capital returned | J18: 3% intrest to be
D19: =SUM(D2:D16) -> 500000 | F19: =SUM(F2:F16) -> 625000 | H19: =F19/D19 -> 1.25 | J19: =(D19)*3/100 -> 15000 | K19: June end
J20: =J19 -> 15000 | K20: July end
J21: =J20 -> 15000 | K21: August end
C25: IN CASE OF DISCONTINUE FROM INVESTMENT CAPITAL WILL START REPAYMENT FROM END OF SEPTEMBER 24
D27: INVESTMENT OF | E27: MIN RETURNS | F27: USED MONTHS | H27: PER MONTH INTREST | I27: TOTAL INTREST TILL DATE ON INVESTMENT | J27: TOTAL AMOUNT TO REPAY
C28: 1st investment | D28: =SUM(D2:D10) -> 500000 | E28: 3 | F28: 11 | H28: =D28*E28/100 -> 15000 | I28: =H28*F28 -> 165000 | J28: =D28+I28 -> 665000
J32: =SUM(J28:J30) -> 665000
H34: REPAYMENT TILL NOW WE MADE | J34: =F19 -> 625000
H36: YOU WILL NEED TO REPAY US BACK TO DISCONTINUE WITH PLANS | J36: =J32-J34 -> 40000 | L36: Repayment will start from September 24 end
L37: =J36/3 -> 13333.333 | M37: Sep end
L38: =L37 -> 13333.333 | M38: Oct end
L39: =L38 -> 13333.333 | M39: Nov end

Sheet aarif Sharif
A1: Transaction types | B1: date of investment | C1: Agreement name | D1: amount of investment | E1: repayment dates | F1: repayment amount
A2: Investment | B2: 21th Aug, 2023 | C2: Aarif Sharrif | D2: 30000
A3: Investment | B3: 22th Aug, 2023 | C3: Aarif Sharrif | D3: 220000
A4: Repayment | C4: Aarif Sharrif | D4: 0 | E4: 31st Aug 2023 | F4: 20000
A5: Investment | B5: 13th Sep 2023 | C5: Aarif Sharrif | D5: 20000
A6: Investment | B6: 23rd Sep 2023 | C6: Aarif Sharrif | D6: 100000
